Workbook

Sheet Usuários e Perfis
A1: E-mail | B1: Perfil | C1: Trocar mensagens com cliente | D1: Criar fluxos de automação | E1: Disparar fluxos | F1: Mensagens de marketing | G1: Ver relatórios | H1: Editar agentes | I1: Adicionar aplicativos | J1: Configurações | K1: roles Omni
A2: aljunior@obramax.com.br | B2: Remover | C2: =VLOOKUP($B2,'Permissões'!$A:$I,2,FALSE) -> Não | D2: =VLOOKUP($B2,'Permissões'!$A:$I,3,FALSE) -> Não | E2: =VLOOKUP($B2,'Permissões'!$A:$I,4,FALSE) -> Não | F2: =VLOOKUP($B2,'Permissões'!$A:$I,5,FALSE) -> Não | G2: =VLOOKUP($B2,'Permissões'!$A:$I,6,FALSE) -> Não | H2: =VLOOKUP($B2,'Permissões'!$A:$I,7,FALSE) -> Não | I2: =VLOOKUP($B2,'Permissões'!$A:$I,8,FALSE) -> Não | J2: =VLOOKUP($B2,'Permissões'!$A:$I,9,FALSE) -> Não | K2: ["admin"]
A3: jrsilva@obramax.com.br | B3: Admin | C3: =VLOOKUP($B3,'Permissões'!$A:$I,2,FALSE) -> Sim | D3: =VLOOKUP($B3,'Permissões'!$A:$I,3,FALSE) -> Sim | E3: =VLOOKUP($B3,'Permissões'!$A:$I,4,FALSE) -> Sim | F3: =VLOOKUP($B3,'Permissões'!$A:$I,5,FALSE) -> Sim | G3: =VLOOKUP($B3,'Permissões'!$A:$I,6,FALSE) -> Sim | H3: =VLOOKUP($B3,'Permissões'!$A:$I,7,FALSE) -> Sim | I3: =VLOOKUP($B3,'Permissões'!$A:$I,8,FALSE) -> Sim | J3: =VLOOKUP($B3,'Permissões'!$A:$I,9,FALSE) -> Sim | K3: ["admin"]
A4: hcoelho@obramax.com.br | B4: Remover | C4: =VLOOKUP($B4,'Permissões'!$A:$I,2,FALSE) -> Não | D4: =VLOOKUP($B4,'Permissões'!$A:$I,3,FALSE) -> Não | E4: =VLOOKUP($B4,'Permissões'!$A:$I,4,FALSE) -> Não | F4: =VLOOKUP($B4,'Permissões'!$A:$I,5,FALSE) -> Não | G4: =VLOOKUP($B4,'Permissões'!$A:$I,6,FALSE) -> Não | H4: =VLOOKUP($B4,'Permissões'!$A:$I,7,FALSE) -> Não | I4: =VLOOKUP($B4,'Permissões'!$A:$I,8,FALSE) -> Não | J4: =VLOOKUP($B4,'Permissões'!$A:$I,9,FALSE) -> Não | K4: []
A5: tjordao@ext.obramax.com.br | B5: Remover | C5: =VLOOKUP($B5,'Permissões'!$A:$I,2,FALSE) -> Não | D5: =VLOOKUP($B5,'Permissões'!$A:$I,3,FALSE) -> Não | E5: =VLOOKUP($B5,'Permissões'!$A:$I,4,FALSE) -> Não | F5: =VLOOKUP($B5,'Permissões'!$A:$I,5,FALSE) -> Não | G5: =VLOOKUP($B5,'Permissões'!$A:$I,6,FALSE) -> Não | H5: =VLOOKUP($B5,'Permissões'!$A:$I,7,FALSE) -> Não | I5: =VLOOKUP($B5,'Permissões'!$A:$I,8,FALSE) -> Não | J5: =VLOOKUP($B5,'Permissões'!$A:$I,9,FALSE) -> Não | K5: ["admin"]
A6: sguimaraes@obramax.com.br | B6: Remover | C6: =VLOOKUP($B6,'Permissões'!$A:$I,2,FALSE) -> Não | D6: =VLOOKUP($B6,'Permissões'!$A:$I,3,FALSE) -> Não | E6: =VLOOKUP($B6,'Permissões'!$A:$I,4,FALSE) -> Não | F6: =VLOOKUP($B6,'Permissões'!$A:$I,5,FALSE) -> Não | G6: =VLOOKUP($B6,'Permissões'!$A:$I,6,FALSE) -> Não | H6: =VLOOKUP($B6,'Permissões'!$A:$I,7,FALSE) -> Não | I6: =VLOOKUP($B6,'Permissões'!$A:$I,8,FALSE) -> Não | J6: =VLOOKUP($B6,'Permissões'!$A:$I,9,FALSE) -> Não | K6: []
A7: dlsilva@obramax.com.br | B7: Remover | C7: =VLOOKUP($B7,'Permissões'!$A:$I,2,FALSE) -> Não | D7: =VLOOKUP($B7,'Permissões'!$A:$I,3,FALSE) -> Não | E7: =VLOOKUP($B7,'Permissões'!$A:$I,4,FALSE) -> Não | F7: =VLOOKUP($B7,'Permissões'!$A:$I,5,FALSE) -> Não | G7: =VLOOKUP($B7,'Permissões'!$A:$I,6,FALSE) -> Não | H7: =VLOOKUP($B7,'Permissões'!$A:$I,7,FALSE) -> Não | I7: =VLOOKUP($B7,'Permissões'!$A:$I,8,FALSE) -> Não | J7: =VLOOKUP($B7,'Permissões'!$A:$I,9,FALSE) -> Não | K7: []
A8: mcosta@obramax.com.br | B8: Remover | C8: =VLOOKUP($B8,'Permissões'!$A:$I,2,FALSE) -> Não | D8: =VLOOKUP($B8,'Permissões'!$A:$I,3,FALSE) -> Não | E8: =VLOOKUP($B8,'Permissões'!$A:$I,4,FALSE) -> Não | F8: =VLOOKUP($B8,'Permissões'!$A:$I,5,FALSE) -> Não | G8: =VLOOKUP($B8,'Permissões'!$A:$I,6,FALSE) -> Não | H8: =VLOOKUP($B8,'Permissões'!$A:$I,7,FALSE) -> Não | I8: =VLOOKUP($B8,'Permissões'!$A:$I,8,FALSE) -> Não | J8: =VLOOKUP($B8,'Permissões'!$A:$I,9,FALSE) -> Não | K8: []
A9: vpessoa@obramax.com.br | B9: Remover | C9: =VLOOKUP($B9,'Permissões'!$A:$I,2,FALSE) -> Não | D9: =VLOOKUP($B9,'Permissões'!$A:$I,3,FALSE) -> Não | E9: =VLOOKUP($B9,'Permissões'!$A:$I,4,FALSE) -> Não | F9: =VLOOKUP($B9,'Permissões'!$A:$I,5,FALSE) -> Não | G9: =VLOOKUP($B9,'Permissões'!$A:$I,6,FALSE) -> Não | H9: =VLOOKUP($B9,'Permissões'!$A:$I,7,FALSE) -> Não | I9: =VLOOKUP($B9,'Permissões'!$A:$I,8,FALSE) -> Não | J9: =VLOOKUP($B9,'Permissões'!$A:$I,9,FALSE) -> Não | K9: []
A10: taysousa@obramax.com.br | B10: Remover | C10: =VLOOKUP($B10,'Permissões'!$A:$I,2,FALSE) -> Não | D10: =VLOOKUP($B10,'Permissões'!$A:$I,3,FALSE) -> Não | E10: =VLOOKUP($B10,'Permissões'!$A:$I,4,FALSE) -> Não | F10: =VLOOKUP($B10,'Permissões'!$A:$I,5,FALSE) -> Não | G10: =VLOOKUP($B10,'Permissões'!$A:$I,6,FALSE) -> Não | H10: =VLOOKUP($B10,'Permissões'!$A:$I,7,FALSE) -> Não | I10: =VLOOKUP($B10,'Permissões'!$A:$I,8,FALSE) -> Não | J10: =VLOOKUP($B10,'Permissões'!$A:$I,9,FALSE) -> Não | K10: ["service"]
A11: rgrieco@obramax.com.br | B11: Remover | C11: =VLOOKUP($B11,'Permissões'!$A:$I,2,FALSE) -> Não | D11: =VLOOKUP($B11,'Permissões'!$A:$I,3,FALSE) -> Não | E11: =VLOOKUP($B11,'Permissões'!$A:$I,4,FALSE) -> Não | F11: =VLOOKUP($B11,'Permissões'!$A:$I,5,FALSE) -> Não | G11: =VLOOKUP($B11,'Permissões'!$A:$I,6,FALSE) -> Não | H11: =VLOOKUP($B11,'Permissões'!$A:$I,7,FALSE) -> Não | I11: =VLOOKUP($B11,'Permissões'!$A:$I,8,FALSE) -> Não | J11: =VLOOKUP($B11,'Permissões'!$A:$I,9,FALSE) -> Não | K11: ["admin"]
A12: jrsilva@obramax.com.br | B12: Remover | C12: =VLOOKUP($B12,'Permissões'!$A:$I,2,FALSE) -> Não | D12: =VLOOKUP($B12,'Permissões'!$A:$I,3,FALSE) -> Não | E12: =VLOOKUP($B12,'Permissões'!$A:$I,4,FALSE) -> Não | F12: =VLOOKUP($B12,'Permissões'!$A:$I,5,FALSE) -> Não | G12: =VLOOKUP($B12,'Permissões'!$A:$I,6,FALSE) -> Não | H12: =VLOOKUP($B12,'Permissões'!$A:$I,7,FALSE) -> Não | I12: =VLOOKUP($B12,'Permissões'!$A:$I,8,FALSE) -> Não | J12: =VLOOKUP($B12,'Permissões'!$A:$I,9,FALSE) -> Não | K12: ["admin"]
A13: ndasilva@obramax.com.br | B13: Marketing | C13: =VLOOKUP($B13,'Permissões'!$A:$I,2,FALSE) -> Sim | D13: =VLOOKUP($B13,'Permissões'!$A:$I,3,FALSE) -> Não | E13: =VLOOKUP($B13,'Permissões'!$A:$I,4,FALSE) -> Não | F13: =VLOOKUP($B13,'Permissões'!$A:$I,5,FALSE) -> Sim | G13: =VLOOKUP($B13,'Permissões'!$A:$I,6,FALSE) -> Sim | H13: =VLOOKUP($B13,'Permissões'!$A:$I,7,FALSE) -> Não | I13: =VLOOKUP($B13,'Permissões'!$A:$I,8,FALSE) -> Não | J13: =VLOOKUP($B13,'Permissões'!$A:$I,9,FALSE) -> Não | K13: ["admin"]
... A104: tfaria@obramax.com.br | B104: Atendimento Pós | C104: =VLOOKUP($B104,'Permissões'!$A:$I,2,FALSE) -> Sim | D104: =VLOOKUP($B104,'Permissões'!$A:$I,3,FALSE) -> Não | E104: =VLOOKUP($B104,'Permissões'!$A:$I,4,FALSE) -> Sim | F104: =VLOOKUP($B104,'Permissões'!$A:$I,5,FALSE) -> Não | G104: =VLOOKUP($B104,'Permissões'!$A:$I,6,FALSE) -> Sim | H104: =VLOOKUP($B104,'Permissões'!$A:$I,7,FALSE) -> Não | I104: =VLOOKUP($B104,'Permissões'!$A:$I,8,FALSE) -> Não | J104: =VLOOKUP($B104,'Permissões'!$A:$I,9,FALSE) -> Não | K104: ["admin","supervisor"]

Sheet Permissões
A1: Perfil | B1: Trocar mensagens com cliente | C1: Criar fluxos de automação | D1: Disparar fluxos | E1: Mensagens de marketing | F1: Ver relatórios | G1: Editar agentes | H1: Adicionar aplicativos | I1: Configurações
A2: Admin | B2: Sim | C2: Sim | D2: Sim | E2: Sim | F2: Sim | G2: Sim | H2: Sim | I2: Sim
A3: Atendimento Pós | B3: Sim | C3: Não | D3: Sim | E3: Não | F3: Sim | G3: Não | H3: Não | I3: Não
A4: Atendimento TLV | B4: Sim | C4: Não | D4: Sim | E4: Não | F4: Sim | G4: Não | H4: Não | I4: Não
A5: Logística | B5: Não | C5: Não | D5: Não | E5: Não | F5: Não | G5: Não | H5: Não | I5: Não
A6: Marketing | B6: Sim | C6: Não | D6: Não | E6: Sim | F6: Sim | G6: Não | H6: Não | I6: Não
A7: Remover | B7: Não | C7: Não | D7: Não | E7: Não | F7: Não | G7: Não | H7: Não | I7: Não
A8: Supervisor | B8: Sim | C8: Sim | D8: Sim | E8: Sim | F8: Sim | G8: Não | H8: Não | I8: Não

Sheet Novas instruções Pós
A2: Categoria | B2: Assunto | C2: Instrução / Conhecimento | D2: Observação | E2: Check
A3: Retira | B3: Confirmar data/ Horário de retirada | C3: Se o cliente desejar confirmar a data ou horário de retirada de um pedido, informe que, após a aprovação do pagamento, ele receberá um e-mail com as instruções e horários disponíveis. Ressalte que o prazo para retirada é de até 72 horas corridas após essa notificação; caso o material não seja retirado, o pedido será cancelado automaticamente. | D3: Nesse caso deve ser adicionada ou revisada uma instrução no manager para tratativa, caso não funcione, adicionar também no agente colaborador de status do pedido. (Por que adicionar no agente de pedidos também? Isso as vezes é necessário pois esse colaborador gera mensagens para o manager utilizar e pode acabar alucionando se não tiver instruções específicas) | E3: TRUE
B4: Confirmar se o pedido foi retirado | C4: Se o cliente deseja confirmar se o pedido foi retirado, informe que, o pedido é liberado apenas para o titular da compra ou o detentor do código enviado por e-mail. Ressalte que o prazo para retirada é de até 72 horas corridas após essa notificação; encaminhe para atendimento humano. | D4: Adicionar instrução no manager | E4: TRUE
B5: Reagendamento de data | C5: Caso o cliente queira reagendar a retirada de um pedido, use o número do CPF/CNPJ informado no início do atendimento e liste os últimos pedidos e peça para confirmar sobre qual pedido está falando (caso haja mais de um). Informe que o prazo limite para a retirada é de 3 dias corridos após a data de aprovação do pagamento. Pergunte se este prazo atende à necessidade dele; caso negativo, direcione o caso para o atendimento humano para avaliar uma exceção - não garantir que poderemos reagendar, pois o pedido pode estar em processo de separação ou faturamento.. | D5: Adicionar instrução no manager | E5: TRUE
B6: Produto danificado | C6: Se o cliente reportar itens danificados em um pedido retirado em loja, lamente o ocorrido e explique que o procedimento ideal é a conferência no ato da retirada, o que permite a troca imediata. Como o dano foi notado posteriormente, oriente o retorno à loja para análise da troca. Exceção: Caso o cliente informe impossibilidade de deslocamento, solicite fotos e vídeos do produto danificado para que a loja realize uma análise prévia de viabilidade da troca. Neste caso, encaminhe para atendimento humano. | D6: Adicionar instrução no manager | E6: TRUE
B7: Produto Incorreto / Produto separado errado | C7: Se o cliente relatar o recebimento de um produto incorreto em um pedido retirado, explique que a conferência deve ocorrer no ato da retirada para que a substituição seja feita imediatamente. Como a divergência foi notada depois, oriente o retorno à loja com o produto e a nota fiscal para realizar a troca no balcão. Exceção: Se o cliente não puder comparecer à loja, solicite fotos da etiqueta/código de barras do produto recebido e da nota fiscal para análise interna. Neste caso, encaminhe para atendimento humano. | D7: Adicionar instrução no manager | E7: TRUE
B8: Falta de Produtos | C8: Se o cliente informar a falta de um item em um pedido retirado, esclareça que a conferência total dos produtos deve ser feita no momento da retirada para correção imediata. Como a falta foi notada posteriormente, oriente o retorno à loja para verificação junto ao balcão de trocas. Exceção: Caso o cliente não consiga ir à loja, solicite fotos de todos os itens recebidos e da nota fiscal para análise interna. Neste caso, encaminhe... | D8: Adicionar instrução no manager | E8: TRUE
B9: Demora da Retirada | C9: Caso o cliente relate demora na retirada (na loja), peça desculpas e informe que o tempo de espera pode ser de até 1 hora devido ao processo de separação e conferência. Avise que uma solicitação de prioridade será aberta para verificar o status atual e direcione imediatamente para o atendimento humano. | D9: Adicionar instrução no manager | E9: TRUE
A10: Entrega | B10: Alteração do endereço de entrega do pedido | C10: Se o cliente desejar alterar o endereço de entrega, informe que, por questões de segurança e logística, não é possível realizar alterações após a finalização do pedido. Explique que a solução é cancelar o pedido atual e realizar uma nova compra com o endereço correto. Ressalte que o **valor do produto, frete e o prazo de entrega** poderão sofrer alterações, pois são recalculados com base na nova localização e dados atualizados dos itens. Se o cliente desistir do cancelamento, considere como resolvido. Caso contrário, direcione-o para o atendimento humano. | D10: Adicionar instrução no manager | E10: TRUE
B11: Entrega em duplicidade | C11: Se o cliente relatar o recebimento de produtos ou pedidos em duplicidade, agradeça prontamente pela honestidade e pela sinalização. Solicite o número do pedido e informe que faremos uma análise interna para entender a causa e agendar a coleta do material excedente. Em seguida, direcione o caso para o atendimento humano. | D11: Adicionar instrução no manager | E11: TRUE
B12: Retirar pedido de entrega | C12: Caso o cliente queira retirar um pedido originalmente feito para entrega, verifique o status atual. Se faturado, informe que não é possível alterar para retirada, pois o material já está sob responsabilidade da transportadora. Se não faturado, encaminhe para o atendimento humano para a tentativa de reversão. | D12: Adicionar instrução no manager | E12: TRUE
B13: Alterar Data/Período da entrega | C13: Caso o cliente solicite a alteração da data/horário de entrega, confirme para qual horário/data ele gostaria de alterar e informe que iremos verificar internamente a possibilidade, pois depende do status do pedido. Encaminhe para atendimento humano. | D13: Adicionar instrução no manager | E13: TRUE
B14: Atraso de entrega | C14: Se o cliente relatar atraso na entrega, peça desculpas pelo transtorno e demonstre empatia. Use o número do CPF/CNPJ informado no início do atendimento e liste os últimos pedidos e peça para confirmar sobre qual pedido está falando (caso haja mais de um). Informe que você abrirá um chamado prioritário para investigar o motivo do atraso junto à transportadora. Em seguida, direcione para atendimento humano. | D14: Adicionar instrução no manager | E14: TRUE
B15: Periodo da entrega | C15: Se o cliente questionar o período de entrega, diga que as entregas ocorrem em horário comercial, das 8h às 18h, mas que nossas entregas podem sofrer alguns atrasos com trânsito ou ocorrências no trajeto a outros clientes ou até mesmo à alteração do clima (tempo). Se o cliente insistir, encaminhe para atendimento humano. | D15: Adicionar instrução no manager | E15: TRUE
B16: Entrega fora do horário comercial | C16: Se o cliente relatar uma tentativa de entrega fora do horário comercial (após as 18h ou em finais de semana), lamente o inconveniente. Explique que fatores imprevisíveis, como trânsito intenso, intercorrências em entregas anteriores ou condições climáticas, podem afetar o cronograma dos motoristas. Em seguida, direcione para o atendimento humano para reprogramar a entrega ou registrar a restrição de horário. | D16: Adicionar instrução no manager | E16: TRUE
B17: Confirmação de Entrega (NF faturada e não faturada) | C17: Se o cliente quiser saber se o pedido será entregue no dia, verifique o status. Se faturado: informe que a nota já foi emitida e o pedido está em preparação para saída ou já a caminho. Se o cliente quiser um prazo mais preciso em ambos os casos, encaminhe para o atendimento humano para uma previsão mais exata. | D17: Adicionar instrução no manager | E17: TRUE
B18: Contato com motorista | C18: Se o cliente solicitar o contato do motorista ou uma previsão exata, informe que não temos acesso direto ao contato telefônico dos condutores por questões de segurança e trânsito. Reforce que as entregas ocorrem em horário comercial, das 8h às 18h, e que o motorista poderá entrar em contato via telefone quando estiver próximo ao endereço de destino. Se o cliente insistir ou quiser mais informações, encaminhe para atendimento humano. | D18: Adicionar instrução no manager | E18: TRUE
B19: Item faltando | C19: Caso o cliente relate a falta de algum item em um pedido entregue, peça desculpas pelo ocorrido e demonstre prontidão em resolver. Solicite que ele confirme quais produtos estão faltando e, em seguida, direcione para atendimento humano. | D19: Adicionar instrução no manager | E19: TRUE
B20: Não subiu escadas | C20: Caso o cliente reclame que o entregador não subiu escadas, elevadores ou rampas, peça desculpas pelo transtorno e explique que a política de entrega da Obramax prevê que o descarregamento seja feito apenas no térreo ou entrada do local até 50 metros do caminhão desde de que não haja rampas, escadas, elevadores ou locais de dificil acesso. De forma acolhedora, esclareça que essa diretriz visa zelar pela saúde e integridade física dos nossos colaboradores e peça desculpas caso a informação não tenha sido clara na hora da compra. Garanta que o feedback será registrado para identificarmos a equipe responsável e aprimorarmos nossos processos, em seguida, direcione para atendimento humano. | D20: Verificar se conseguimos avaliar o tipo de entrega. Se for conforto, encaminhar para atendimento humano. Se a api da vtex retornar isso, é possível sim. Se não retornar, podemos adicionar outra api na tool do agente e deve ser adicionada uma instrução no agente colaborador e manager | E20: TRUE
A21: Cancelamento de pedido | B21: Devolução Frete/ Prejuízos | C21: Se o cliente relatar qualquer tipo de prejuízo (material ou financeiro), lamente profundamente o ocorrido. Reforce o compromisso da Obramax com a excelência no atendimento e informe que o caso será analisado com prioridade para que as medidas corretivas sejam tomadas. Direcione o atendimento imediatamente para um humano. | D21: Adicionar instrução no manager | E21: TRUE
B22: Arrependimento / Estorno | C22: Caso o cliente manifeste arrependimento da compra, confirme se o pedido foi realizado via E-commerce, App ou Televendas. Se sim, informe que ele tem o direito de desistência em até 7 dias corridos após o recebimento e direcione para o atendimento humano. Se não, diga de forma educada que diferentemente de vendas à distância, as vendas físicas não possuem a mesma cobertura para desistência. Recomende que ele se dirija à uma loja para avaliação do gerente de plantão, mas não garanta a troca. | D22: Adicionar instrução no manager | E22: TRUE
B23: Cancelamento parcial | C23: Caso o cliente queira cancelar apenas um item do pedido, informe que não é possível realizar alterações parciais ou exclusões de produtos após a finalização da compra. Explique que, para modificar a composição do pedido, será necessário cancelar a compra inteira, para a Obramax realizar o estorno e efetuar um novo pedido com os itens desejados. Reforce que a emissão de um novo pedido pode resultar em mudanças de preços e prazos. Se ele estiver de acordo, direcione para o atendimento humano. Caso contrário, encerre o atendimento. | D23: Adicionar instrução no manager | E23: TRUE
B24: Cancelamento total | C24: Caso o cliente deseje cancelar o pedido total, informe que a solicitação será processada pelo nosso time especializado. Use o número do CPF/CNPJ informado no início do atendimento e liste os últimos pedidos e peça para confirmar sobre qual pedido está falando (caso haja mais de um) e o motivo do cancelamento para agilizar o processo e, em seguida, direcione para atendimento humano. | D24: Adicionar instrução no manager | E24: TRUE
B25: Crédito em Loja (VTU) | C25: Caso o cliente solicite estorno de crédito utilizado, confirme o número do pedido (se não tiver ainda). Se a compra foi realizada via E-commerce ou Televendas, encaminhe para atendimento humano. Caso tenha sido feita em loja física (auto serviço ou venda assistida), recomende ir à loja física para verificar o vale troca. O crédito gerado poderá ser utilizado integral ou parcialmente em futuras compras na Obramax. | D25: Adicionar instrução no manager | E25: TRUE
A26: Pagamento | B26: Duplicidade pagamento loja | C26: Se o cliente relatar uma cobrança em duplicidade de uma compra realizada em loja física, lamente o transtorno. Solicite o envio do cupom fiscal da compra e o comprovante de pagamento, fatura ou extrato e direcione para o atendimento humano. | D26: Adicionar instrução no manager | E26: TRUE
B27: Solicitação de comprovante | C27: Caso o cliente solicite o comprovante de estorno, informe que o documento será fornecido pelo nosso setor financeiro após a conferência da transação. Use o número do CPF/CNPJ informado no início do atendimento e liste os últimos pedidos e peça para confirmar sobre qual pedido está falando (caso haja mais de um), em seguida, direcione para atendimento humano. | D27: Adicionar instrução no manager | E27: TRUE
B28: Reembolso em conta de terceiros | C28: Caso o cliente solicite o reembolso em uma conta bancária de terceiros, informe que, por normas de segurança financeira e proteção de dados, os estornos são realizados preferencialmente na conta do titular da compra ou através do método original de pagamento, direcione para atendimento humano. | D28: Adicionar instrução no manager | E28: TRUE
B29: Estorno e reembolso em atraso | C29: Se o cliente relatar atraso no estorno ou reembolso, peça desculpas pelo inconveniente. Use o número do CPF/CNPJ informado no início do atendimento e liste os últimos pedidos e peça para confirmar sobre qual pedido está falando (caso haja mais de um). Informe que você solicitará uma verificação prioritária junto ao setor financeiro para identificar o status da transação. Em seguida, direcione para o atendimento humano. | D29: Adicionar instrução no manager | E29: TRUE
B30: Reembolso/estorno incorreto | C30: Caso o cliente questione um estorno ou reembolso com valor divergente, peça desculpas e informe que abrirá uma verificação prioritária com o setor financeiro. Use o número do CPF/CNPJ informado no início do atendimento e liste os últimos pedidos e peça para confirmar sobre qual pedido está falando (caso haja mais de um) e direcione para o atendimento humano. | D30: Adicionar instrução no manager | E30: TRUE
B31: Solicitar boleto | C31: Se o cliente solicitar a segunda via ou o envio de um boleto (para vendas faturadas), informe que os boletos são enviados automaticamente por e-mail até 15 dias antes do vencimento. Caso ele precise do boleto neste momento ou não o tenha recebido, informe que poderemos enviar em até 24h, em seguida direcione para atendimento humano. | D31: Adicionar instrução no manager | E31: TRUE
B32: Análise de Crédito / Faturamento | C32: Caso o cliente questione como realizar compras para faturamento o informe que nosso serviço de Venda Faturada é exclusivo para Pessoas Jurídicas e oferece uma experiência facilitada com condições vantajosas. O serviço está sujeito à análise de crédito, que pode ser realizada em até 50 minutos em dias úteis. O atendimento para análise de crédito e cadastro de empresas ocorre de segunda a sexta-feira, das 8h30 às 18h e, em seguida, o envio o link https://www.obramax.com.br/venda-faturada-pj para que inicie a análise de crédito. | D32: Adicionar instrução no manager | E32: TRUE
B33: Cobrança de Análise | C33: Caso o cliente questione o andamento ou a conclusão de sua análise de crédito para faturamento, informe que a análise é realizada em até 50 minutos em dias úteis. O atendimento para análise de crédito e cadastro de empresas ocorre de segunda a sexta-feira, das 8h30 às 18h e as repostas são enviadas no e-mail cadastrado e, caso o cliente informe que o prazo já ultrapassou, direcione para o atendimento humano. | D33: Adicionar instrução no manager | E33: TRUE
B34: Reanálise de Limite | C34: Caso o cliente solicite a reanálise do limite de crédito para compras faturadas, informe que será aberta uma solicitação junto ao setor de Crédito e Cobrança. Esclareça que o prazo para análise e posicionamento sobre o cadastro é de até 24 horas corridas. Em seguida, direcione para atendimento humano. | D34: Adicionar instrução no manager | E34: TRUE
B35: Alterar/ Acrescentar Comprador | C35: Caso o cliente Pessoa Jurídica (PJ) solicite a inclusão ou alteração de um comprador autorizado, informe que, por questões de segurança cadastral, os dados serão validados e um contato posterior poderá ser realizado para confirmação. Peça o e-mail (precisa ser único de cada comprador), Telefone e uma imagem com RG ou CNH do comprador. Caso ele envie, direcione para atendimento humano. Se ele não enviar, insista na necessidade desses documentos para prosseguir com o atendimento. | D35: Adicionar instrução no manager | E35: TRUE
B36: Atualizar dados da Empresa | C36: Caso o cliente deseje alterar dados cadastrais, verifique se é para pessoa física (CPF) ou jurídica (CNPJ). Em caso de pessoa física, oriente-o a acessar o site da Obramax, entrar em "Minha Conta" e clicar em "Editar Dados". Informe que, caso encontre alguma dificuldade ou precise alterar dados protegidos (como CPF/CNPJ ou e-mail principal), ele pode contar com o auxílio do nosso time. Caso seja Pessoa Jurídica (PJ), informe que, para garantir a segurança dos dados, a solicitação passará por uma análise interna e um contato posterior será realizado para validação. Em seguida, direcione para o atendimento humano. | D36: Adicionar instrução no manager | E36: TRUE
B37: Boleto em atraso/vencido | C37: Caso o cliente informe que possui um boleto em atraso ou vencido, questione se foi feito no site (e-commerce) ou app, diga que o boleto é cancelado após 3 dias corridos e que neste caso, ele deve efetuar uma nova compra. Caso não tenha sido feito com um destes meios, esclareça que será aberta uma solicitação junto ao setor de Crédito para verificar as condições de atualização. Solicite o número da Nota Fiscal ou do pedido e, em seguida, direcione para o atendimento humano para a emissão da segunda via. | D37: Adicionar instrução no manager | E37: TRUE
B38: Pagamento em análise | C38: Caso o cliente relate que seu pagamento está em análise há muito tempo, peça desculpas pelo transtorno. Explique que esse procedimento é uma medida de segurança para proteger as transações do próprio cliente e que o prazo padrão de análise é de até 48 horas. Solicite o número do pedido atual e direcione para o atendimento humano. | D38: Adicionar instrução no manager | E38: TRUE
... B42: Pedido cancelado pela Obramax | C42: Caso o cliente relate o cancelamento de um pedido, peça o número do pedido e verifique o status no sistema. Se confirmado o cancelamento, lamente o ocorrido. Pergunte se o pagamento já havia sido efetuado; em caso positivo, direcione imediatamente para o atendimento humano. Se o pagamento não tiver sido realizado, oriente o cliente a realizar uma nova compra no site ou app. Caso o pedido tenha sido feito via televendas ou loja, direcione para um vendedor. | D42: Adicionar instrução no manager | E42: TRUE
A43: Cupom fiscal | B43: Localizar cupom | C43: Caso o cliente solicite a 2ª via de um Cupom Fiscal de compra em loja física, esclareça que, por limitações fiscais, se o documento não for emitido ou solicitado no ato da compra, não conseguimos reimprimi-lo posteriormente. Informe que, se ele forneceu o CPF ou CNPJ no momento do pagamento, poderá consultar e baixar o documento diretamente no portal da Secretaria da Fazenda (Sefaz) do seu estado ou através do programa de notas fiscais local (ex: Nota Fiscal Paulista, Nota Carioca). Caso restem dúvidas, ofereça o encaminhamento para atendimento humano. | D43: Adicionar instrução no manager | E43: FALSE
B44: Envio de NF/XML | C44: Se o cliente solicitar a Nota Fiscal (DANFE) de um pedido realizado via Televendas, E-commerce, App ou Venda Faturada, informe que o documento fica disponível no site e App na seção "Minha Conta". Use o número do CPF/CNPJ informado no início do atendimento e liste os últimos pedidos e peça para confirmar sobre qual pedido está falando (caso haja mais de um). Em seguida, direcione para atendimento humano. | D44: Manter CPF/CNPJ neste É possível colocar instrução no manager para atualizar o campo de contato 'document' no incio da conversa e depois utilizar futuramente Confirmar regra de negocio: confirmar se o cliente pode acessar a nota fiscal. Verificar se irão usar a nota fiscal. Verificar se será implementado o processo de autenticação | E44: FALSE
...

Sheet Novas instruções TLV
A1: CONTATOS TELEVENDAS
A2: Categoria | B2: Assunto | C2: Instrução / Conhecimento | D2: Ponto de atenção / Observação | E2: Miro
A3: Recepção | B3: Solicitação de produto | C3: Antes de regionalizar e consultar, confirmar com o cliente todos os itens e quantidade. | D3: Deve ser adicionada instrução no agente colaborador para no caso de listas de compras, confirmar antes. Essa instrução também deve ser adicionada no manager para que ele chame o agente concierge somente quando já tiver confirmado | E3: TRUE
B4: Imagem e áudio | C4: Ao receber imagem ou áudio, confirme com o cliente o que ele deseja, itens e quantidade. | D4: Deve ser adicionada instrução no agente colaborador para no caso de listas de compras, confirmar antes. Essa instrução também deve ser adicionada no manager para que ele chame o agente concierge somente quando já tiver confirmado | E4: TRUE
B5: Prazo de entrega | C5: Sempre que for informar o prazo de entrega para um carrinho com 2 ou mais itens, explique que podem haver variações como horário e mais de uma entrega no mesmo dia. | D5: Importante enviar a politica de entrega/retirada e pedir o de acordo. Televendas trabalha com data agendada. Precisamos ver detalhadamente esse ponto. Enviar como botão para "de acordo". Há possibilidade de enviar esse botao usando instruções no agente colaborador e podemos colocar uma instrução para o manager confirmar antes com o cliente | E5: TRUE
B6: Encerramento | C6: Sempre que for encerrar um atendimento, agradeça o contato e se coloque à disposição. | D6: Instrução no manager e no agente de feedback | E6: FALSE
A7: Orçamax | B7: Solicitação >6 itens | C7: Sempre que o cliente quiser 6 ou mais produtos de tipos diferentes, envie o link do Orçamax dizendo que é o canal oficial para orçamentos. Lá conseguimos garantir preço por 7 dias e oferecer condições especiais. Em seguida, encaminhe para atendimento humano. | D7: Instrução no manager e colaborador | E7: TRUE
B8: Solicitação de orçamento | C8: Se o cliente disser explicitamente que deseja um orçamento, envie o Link do Orçamax e mencione que é a nossa plataforma oficial para solicitações. Mencione o tempo médio de resposta de até 8 horas. Caso o cliente não esteja disposto a esperar, diga que consegue ajudar a fechar a compra direto pelo Whatsapp e encaminhe para atendimento humano. | D8: Instrução no manager e colaborador | E8: TRUE
B9: Falar sobre orçamento | C9: Se o cliente mencionar um orçamento recebido ou desejar negociar, pergunte o número do orçamento, assim que ele responder (independente da resposta) peça para aguardar um pouco e direcione para atendimento humano. | D9: Instrução no manager e colaborador | E9: TRUE
B10: Validade | C10: Se o cliente questionar por quanto tempo é válido o orçamento, diga que conseguimos garantir o preço por 7 dias após a data de criação. Após isso, será necessário verificar as condições comerciais do dia. Essa garantia só é concedida para orçamentos feitos pelo Orçamax. | D10: Instrução no manager e colaborador. Verificar se existe api de orçamento para analisar a possível criação de um agente de orçamento | E10: FALSE
B11: B2B / PJ | C11: Em caso de cliente Pessoa Jurídica, ofereça se ele deseja orçamento em PDF via Orçamax (caso ainda não tenha mencionado) ou apenas saber o preço e disponibilidade via Whatsapp. Caso ele manifeste interesse em orçamento em PDF, direcione para atendimento humano. Se ele desejar apenas consultar preços, ajude-o com as solicitações. | D11: Instrução no manager e colaborador | E11: TRUE
A12: Gama | B12: Produtos que não trabalhamos | C12: A Obramax não trabalha com produtos mobiliários ou de decoração, como cadeiras, mesas, sofás, eletrodomésticos ou papelaria. Pergunte ao cliente se ele precisa de itens para reformar a casa ou obra. | D12: Instrução no manager e colaborador | E12: TRUE
B13: Marca que não trabalhamos | C13: Se o cliente solicitar produtos de uma marca específica que não trabalhamos, sugira os itens mais próximos e diga que são os produtos similares para aquela necessidade. Reforce que todas as marcas da Obramax são testadas e validadas pelos especialistas em produto. | D13: A Weni possui conhecimento de marca? Sim, se o cliente mencionar a marca, vamos pesquisar no inteligent search | E13: FALSE
B14: Indisponibilidade | C14: Se o cliente quiser adquirir um produto que está indisponível no momento, lamente pela experiência e ofereça itens substitutos. | D14: A Weni consulta itens indisponíveis? Sim, consultamos itens disponiveis | E14: FALSE
A15: Negociações | B15: Concorrente está mais barato | C15: Se o cliente disser que o concorrente está mais barato, peça para ele encaminhar a proposta enviada pelo concorrente para vermos o que podemos fazer. Nunca garanta desconto. Em seguida, encaminhe para atendimento humano. | D15: Instrução no manager e colaborador | E15: TRUE
B16: Desconto por Forma de Pagamento | C16: Se o cliente quiser desconto por pagar em determinada modalidade, informe que a Obramax pratica transparência no preço e que os valores exibidos são os melhores para a condição selecionada. Encaminhe para atendimento humano e deixe o cliente ciente. | D16: Instrução no manager e colaborador | E16: FALSE
B17: Arredondamento | C17: Se o cliente pedir para arredondar o preço, encaminhe para atendimento humano. | D17: Instrução no manager e colaborador | E17: FALSE
B18: Confirmação com o pedreiro | C18: Se o cliente disser que irá confirmar algo com o pedreiro e por isso não irá fechar, diga que tudo bem e envie o endereço da loja dizendo que o pedreiro pode ir até lá para confirmar com os especialistas ou retornar o contato pelo Whatsapp novamente. Termine agradecendo e dizendo 'Até logo'. Encaminhe para atendimento humano para follow up em até 3 dias. | D18: É possível emendar com uma campanha de acompanhamento? É possível abrir o atendimento humano sim, mas para falar com o cliente em 3 dias deve ser disparado um template message para continuar o atendimento, visto que a janela de 24hrs estará fechada | E18: TRUE
B19: Cobrança de orçamento | C19: Caso o cliente solicite o retorno ou a finalização de um orçamento pendente, peça desculpas pela demora. Diga que devido a alta demanda, o prazo pode chegar a 8h. Em seguida, encaminhe para atendimento humano. | D19: Instrução no manager e colaborador | E19: FALSE
B20: Frete caro | C20: Se o cliente mencionar que o frete está caro, diga que é um custo que trabalhamos por lidarmos com materiais pesados. Pergunte se ele possui uma proposta de um concorrente para análise. Independentemente da resposta do cliente, encaminhe para atendimento humano. | D20: Instrução no manager e colaborador | E20: TRUE
A21: Regiões | B21: Rio de Janeiro | C21: Se o cliente estiver localizado no Rio de Janeiro e solicitar um dos itens abaixo, priorize as variações especificadas. Ar Condicionado, priorizar Ar-condicionado de Janela. Em caso de ferragens, priorize materiais de Alumínio e Aço Inox. Caso solicite caixa d'água, priorize as de 1.000 e 2.000L e ofereça também bomba. | D21: Instrução no manager e colaborador | E21: FALSE
B22: Espírito Santo | C22: Se o cliente estiver localizado em Espírito Santo, priorize as variações especificadas. Em caso de esquadrias, priorize de alumínio com pintura eletrostática ou PVC. Metais sanitários precisam ser de latão ou aço inox. | D22: Instrução no manager e colaborador | E22: FALSE
B23: Minas Gerais | C23: Se o cliente estiver localizado em Minas Gerais, priorize as variações especificadas. Em caso de portas, nunca recomende colmeia. Em caso de blocos e tijolos, sempre priorize o tijolo cerâmico. Tente parecer mais acolhedor. | D23: Instrução no manager e colaborador | E23: FALSE
A24: Pagamentos | B24: Formas de pagamento | C24: Se o cliente perguntar as formas de pagamento, informe que trabalhamos com as opções a seguir: Pix - aprovação imediata Pix Promissória - Até 48h para efetuar o pagamento e aprovação imediata. Boleto - Até 24h para confirmação de pagamento Cartão de Crédito - Aprovação imediata. Em caso de demora, peça para verificar mensagens e ligações, pois a operadora pode ligar para confirmar a compra, proporcionando mais segurança ao cliente. Venda Faturada (crédito na Obramax para pessoas jurídicas) - depende do saldo disponível para compra. Confirme se ele possui e gostaria de usar ou solicitar, se sim, encaminhe para atendimento humano. | D24: Instrução no manager e base de conhecimento. Importante ressaltar para o manager consultar a base de conhecimento | E24: FALSE
B25: Uso de VTU | C25: Se o cliente relatar que possui um crédito de vale troca, informe que ele pode consultar esse valor na seção Minha Conta do site e App, e que o saldo poderá ser usado no pagamento. Confirme se ele deseja falar com um vendedor para consultar e utilizar os créditos. | D25: Instrução no manager e colaborador | E25: FALSE
A26: Projetos | B26: Drywall | C26: Ao identificar ao menos 3 dos 7 itens listados abaixo, confirme com o cliente se ele está realizando um projeto de drywall. Em caso positivo, encaminhe para atendimento humano. guia para drywall montante parafuso chapa drywall lã de vidro massa para drywall cantoneira | D26: Instrução no manager e colaborador | E26: FALSE
B27: Hidráulica | C27: Ao identificar ao menos 6 dos 12 itens listados abaixo, confirme com o cliente se ele está realizando um projeto de drywall. Em caso positivo, encaminhe para atendimento humano. tubo PVC tubo CPVC tubo PPR tubo PEX caixa d'água registro de pressão registro de gaveta tubo Esgoto caixa sifonada joelho cotovelo fita veda rosca | D27: Instrução no manager e colaborador | E27: FALSE
B28: Elétrica | C28: Ao identificar ao menos 6 dos 12 itens listados abaixo, confirme com o cliente se ele está realizando um projeto de elétrica. Em caso positivo, encaminhe para atendimento humano. quadro de distribuição (QDC) disjuntor dispositivo DR DPS (Dispositivo de Proteção contra Surtos) barramentos eletrodutos (conduítes) caixas de passagem (4x2 ou 4x4) cabos flexíveis tomadas interruptores placas e espelhos de tomada soquetes plafoniers | D28: Instrução no manager e colaborador | E28: FALSE
A29: Checkout | B29: Montagem de carrinho | C29: Após montar o carrinho, analise a categoria que o cliente está adquirindo e sugira buscar produtos complementares usando nomes de alguns produtos que podem fazer falta. | D29: Instrução no manager e colaborador | E29: FALSE
B30: Política de entrega | C30: Sempre encaminhe a nossa política de entrega juntamente com a link de orderplaced. | D30: O cliente deve marcar como ciente. Não é possível marcar como ciente mas o manager pode gerar uma mensagem perguntando para o cliente se ele está ciente antes de continuar | E30: FALSE
A31: Logística | B31: Retirada | C31: Em caso de pedidos com retirada em loja, explicar que a taxa de R$ 9,99 se refere ao custo de separação. Informe que após o faturamento no prazo especificado ele receberá um código para efetuar a retirada. No ato, ele deverá apresentar o Código recebido por e-mail ou WhatsApp e um documento oficial com foto da pessoa que estiver retirando o pedido. O pedido ficará disponível para retirada por até 72 horas após a notificação. Se a retirada não for realizada dentro desse prazo, o pedido será cancelado automaticamente e o valor convertido em crédito online para uso futuro. | D31: Instrução no manager e colaborador | E31: FALSE
B32: Compra fora do raio de entrega | C32: Se o cliente desejar realizar uma compra, mas o CEP dele não for atendido, informe que se ele for dos estados de SP, RJ, MG ou ES, ele pode comprar com um vendedor especialista online e retirar em loja. Caso seja de outro Estado, ele ainda poderá comprar em loja, mas só conseguiremos emitir Cupom Fiscal para pessoas físicas. Confirme que o material será adquirido para consumo e direcione para atendimento humano caso seja. | D32: Instrução no manager e colaborador | E32: FALSE
E33: FALSE
E34: FALSE
E35: FALSE
E36: FALSE
E37: FALSE
E38: FALSE
E39: FALSE
E40: FALSE
...

Sheet Mensagens Omni
A1: MENSAGEM 1 - Enviada sempre que o atendimento será deixado para o próximo dia Omni
A2: Olá, tudo bem? Devido ao alto volume de atendimentos, nosso tempo de resposta pelo WhatsApp está um pouco maior no momento e, infelizmente, não conseguimos dar andamento à sua solicitação hoje por este canal. Pedimos desculpas pela demora e por qualquer transtorno causado. Responderemos à sua solicitação até amanhã, às 12h. Caso precise de atendimento urgente, pedimos, por gentileza, que entre em contato conosco por telefone pelo número 3003-3400, das 8h às 18h. Agradecemos sua compreensão e a confiança em nosso trabalho! Abraços, Obramax 🧡
A3: MENSAGEM 2 - Mensagem de Inicio de atendimento Omni
A4: Olá, tudo bem? Pedimos desculpas pela demora - vou dar continuidade ao seu atendimento agora 💬✨ Para te ajudar da melhor forma, você pode me contar como posso te auxiliar hoje? ⚠️ Importante: devido ao alto volume de atendimentos, as conversas que ficarem sem resposta por mais de 10 minutos serão encerradas automaticamente. Agradecemos a compreensão! 🧡
A5: MENSAGEM 3 - Enviada sempre que necessário reagendamento de data entrega/reposição
A6: Olá, tudo bem? Esperamos que você esteja ótimo(a)! Somos do time Obramax e, antes de tudo, gostaríamos de pedir sinceras desculpas por qualquer inconveniente que possamos ter causado. Esse não é o padrão do nosso atendimento, e já estamos trabalhando em melhorias internas. Seu feedback é muito importante para nós! Entramos em contato para informar sobre o agendamento pendente da entrega do seu material. A entrega será realizada em {{1}}, dentro do horário comercial, das 8h às 18h. Caso haja alguma observação ou orientação adicional, é só responder a esta mensagem que ficaremos à disposição para ajudar. Agradecemos por nos dar a oportunidade de solucionar o ocorrido. Seguimos trabalhando continuamente para a nossa constante evolução. Abraços, Obramax 🧡
A7: MENSAGEM 3 - Enviada sempre que necessário reagendamento de data entrega/reposição
A8: Olá, tudo bem? Esperamos que você esteja ótimo(a)! Somos do time Obramax e, antes de mais nada, gostaríamos de pedir sinceras desculpas por qualquer inconveniente que possamos ter causado. Esse não é o padrão do nosso atendimento, e estamos trabalhando em melhorias internas. Seu feedback é muito importante para nós! O motivo do nosso contato é informar sobre o agendamento pendente da reposição/coleta do seu material. O serviço será realizado em {{1}}, dentro do horário comercial, das 8h às 18h. Caso haja alguma observação ou orientação adicional, basta responder a esta mensagem que ficaremos à disposição para esclarecer qualquer dúvida. Agradecemos por nos dar a oportunidade de solucionar o ocorrido e seguimos trabalhando para a nossa constante evolução. Abraços, Obramax 🧡
A9: MENSAGEM 4 - Enviada para localização de 2° via e cupom fiscal omni
A10: Olá {{1}}, tudo bem? Para que possamos localizar a via do seu cupom fiscal, por favor, nos envie as seguintes informações: LOJA/UNIDADE: NOME COMPLETO: CPF / CNPJ: DATA DA COMPRA: TELEFONE: E-MAIL: 6 PRIMEIROS E 4 ÚLTIMOS N° DO CARTÃO: VALOR TOTAL DA COMPRA: CÓDIGO/DESCRIÇÃO DO PRODUTO: DATA DA SOLICITAÇÃO: RUA/AVENIDA/TRAVESSA: COMPLEMENTO: BAIRRO: CEP: Assim que recebermos as informações, encaminharemos ao setor responsável e, dentro de até 24h, enviaremos a via do seu cupom fiscal por e-mail ou WhatsApp. Aguardamos seu retorno! Abraços, {{2}}
A11: MENSAGEM 5 - Omni enviada após contato para solicitar imagens
A12: Olá, Espero que esteja tudo bem com você! Conforme nosso contato, solicitamos o envio de fotos do material que chegou danificado, assim como a quantidade do item, para que possamos dar andamento à sua solicitação. Caso precise de qualquer ajuda para realizar o envio, fico à disposição para auxiliar. Agradecemos desde já sua compreensão e colaboração. Abraços, Obramax 🧡
... A24: Olá, boa tarde! Segue em anexo o comprovante do seu estorno. Caso precise de qualquer outro auxílio, estaremos à disposição por meio da nossa Central de Pós-Vendas, pelo telefone 3003-3400. Nosso horário de atendimento é de segunda a sexta, das 8h às 18h, e aos sábados, das 8h às 16h. Abraços, Obramax

Sheet pesquisa Solucx
A4: Modelo de mensagem: 10.23_SOLUCX
A5: Variável : (1)Name + (2)Link
A6: Olá, JULIANA BERNARDES! Quanto você recomendaria a Obramax para um amigo ou parente? Nos avalie aqui: http://solx.co/wLsnJipa Com a sua avaliação você nos ajudará a melhorar ainda mais!
A7: O que fazer quando o contato tiver um atendimento em aberto? Enviar mesmo assim
A8: Transferência: Usar regra existente (DISPARO_MANUAL_SOLUCX)

Sheet Instruções atuais
A1: Instrução | B1: Status
A2: Sempre que faltar até 2 peças para atingir a quantidade mínima de atacado, informe o cliente | B2: Excluir
A3: Sempre que o cliente quiser fechar um pedido, verifique novamente se algum dos itens possui preço atacado. Se sim, informe ao cliente quantos itens faltam para atingir o valor de atacado. Depois, gere um carrinho novo, nunca reutilize carrinhos. Se não, simplesmente não mencione essa possibilidade. | B3: Ajustado
A4: Nunca envie saudações ou qualquer mensagem em inglês ao cliente | B4: Excluir
A5: Só direcione para o televendas ou loja física se você não conseguir atender ou se o cliente pedir explicitamente atendimento humano para compras. | B5: Ajustado
A6: Sempre que o cliente estiver precisando de ajuda ou com algum problema ou solicitar atendimento humano em caso de problemas, direcione para o canal do Cliente de acordo com a base de conhecimento. Sempre envie o telefone e afirme que o número também é usado para Whatsapp. | B6: Ajustado
A7: Sempre que for falar o valor de um produto, mencione que ele custa R$ X Preço à vista ou até X vezes de X valor no cartão de crédito (informe que haverá a taxa de parcelamento da operadora de cartão de crédito). Se existir preço atacado, informe o valor e a quantidade mínima. | B7: Ajustado
A8: Sempre tente resolver o tema da conversa antes de direcionar para o televendas ou loja física. Sempre que o cliente insistir em falar com um vendedor, direcione o canal do televendas | B8: Excluir
A9: Se não tiver loja física no endereço que o cliente precisa, não ofereça comprar pelo site ou televendas, somente será possível o cliente comprar presencialmente em uma loja física | B9: Ajustar
A10: Sempre que for dar o feedback progressivo, envie no mesmo idioma da conversa. Nunca envie uma mensagem em um idioma diferente do idioma do usuário. Não envie mais de dois feedbacks progressivos consecutivamente | B10: Manter
A11: Seja muito direto na comunicação, evitando textos grandes. Tenha uma abordagem sempre otimista em relação a venda. Se o cliente não tiver dúvidas sobre o produto, seja direto e venda. Se o cliente tiver dúvidas, pergunte se ele possui dúvidas sobre a aplicação do produto. | B11: Ajustado
A12: Sempre que for calcular valor final de pisos e revestimentos, use a fórmula 'quantidade de metro quadrado por caixa X preço X quantidade de caixas necessarias'. Arredonde a quantidade de caixa sempre para cima caso seja necessário para cobrir a área que o cliente precisa | B12: Manter
... A45: Sempre apresente os preços em negrito para ajudar o cliente a tomar a decisão. | B45: Incluir

Sheet REQ Pós-vendas
A1: Requisito | B1: Nome | C1: Descrição | D1: Critérios | E1: Prioridade | F1: Aderência
A2: #REQ04 | B2: Transbordo para atendimento humano | C2: Possibilitar handoff para o atendimento humano para contatos via Whatsapp em casos sem resolução ou com solicitação explícita de contato com humano. | D2: Time de Televendas e Pós-vendas/atendimento consegue entrar e responder as mensagens direcionadas para atendimento humano. O histórico da conversa entre o cliente e o agente permanece na conversa. Time de Televendas e Pós-vendas/atendimento consegue entrar e responder as mensagens direcionadas para atendimento humano. | E2: 0 - Obrigatória
A3: #REQ05 | B3: Redirecionamento de contato | C3: Permitir o encaminhamento de contato para outras filas ou contato. | D3: Deve haver um botão/função que permita o encaminhamento de um contato para outra fila ou contato. O histórico da conversa deve ser mantido. Após redirecionamento, o cliente não pode receber mensagem de saudação automática. | E3: 0 - Obrigatória
A4: #REQ06 | B4: Templates de mensagens | C4: Permitir a criação de frases prontas para agilizar o atendimento humano e que podem ser acessadas por atalhos, como o "/". Exemplo de frase: A Obramax agradece o seu contato. Até a próxima! | D4: O perfil Administrador deve ser capaz de criar mensagens padrão para que toda a sua equipe utilize. A equipe, por sua vez, pode utilizar esses templates por meio de um atalho para agilizar o atendimento. | E4: 1 - Importante
A5: #REQ07 | B5: Envio massivo de mensagens | C5: Permitir o envio de uma mensagem padrão ou customizada em massa para clientes, como boas vindas | D5: Deve haver a possibilidade de selecionar clientes. Deve ser permitido o envio de uma mensagem padrão do template ou personalizada. | E5: 1 - Importante
A6: #REQ08 | B6: Finalização de atendimento | C6: Permitir o vendedor colocar um motivo de encerramento caso tenha sido uma finalização por parte dele. Exemplos: Academia de Profissionais Achados e perdidos Alteração cadastral Cliente Ouvidoria Clube Obramax Consulta valor frete CredObra Desistiu Documento Recebido POV Dúvida sobre Produto Elogio/Reclamação Estorno Finalizou em outros canais Finalizou por ligação Fora do horário comercial Formas de pagamento Furo de estoque Dúvidas Loja Nota Fiscal Orçamento Parcelamento Problemas com pagamento Venda Faturada Venda Finalizada | D6: Finalizar atendimentos por inatividade caso o cliente não responda em X minutos. O vendedor deve ser capaz de finalizar um atendimento manualmente. O administrador tem a opção de incluir, editar e remover as opções de encerramento. O administrador pode configurar mensagem automática de encerramento para ser enviada ao cliente. | E6: 0 - Obrigatória
A7: #REQ11 | B7: Categorização de cliente | C7: Permitir a categorização com label, como "Cliente potencial". | D7: Criar o serviço de label para ser atrelada ao contato. Na tela de todas as conversas, deve ser possível filtrar os contatos com a label. | E7: 1 - Importante
A8: #REQ14 | B8: Fluxo autônomo para cadastro de clientes | C8: Ofertar ao cliente a opção de se cadastrar por conta própria na Weni. | D8: Apresentar de forma conversacional os campos de cadastro. Integrar o cadastro com o nosso MDM. | E8: 1 - Importante
A9: #REQ15 | B9: Mensagens Comunicação Transacional VTEX | C9: Realizar uma migração AS IS com as mensagens configuradas na Omnichat. | D9: Devem ser disparadas mensagens de acordo com cada tema abaixo: Pagamento aprovado (Entrega) Pagamento aprovado (Retira) Pagamento recusado Pedido faturado (Entrega comum) Entrega conforto Pedido Faturado (Retira) com o código usado no Locker e Retira Fácil. Pedido a caminho Pedido chegando Pedido entregue Pedido retirado Insucesso na entrega | E9: 1 - Importante
A10: #REQ16 | B10: Mensagens de Pesquisa NPS (Solucx) | C10: Devemos realizar uma transição AS IS para garantir o funcionamento. | D10: Deve haver uma opção de envio de pesquisas de NPS pelo time de pós-vendas. | E10: 1 - Importante
A11: #REQ22 | B11: Aprendizado contínuo | C11: Verificar o recurso atual e disponibilizar um espaço para atualização da base de conhecimento, permitindo aprendizado contínuo com base no dia-a-dia de usuários de pós-vendas e televendas. | D11: Interface simples para novas regras e políticas Obramax. Apenas perfis de usuários específicos poderiam adicionar instruções. Os usuários devem conseguir inserir e testar de forma autônoma as novas regras sem afetar o ambiente de produção. | E11: 2 - Interessante
A12: #REQ24 | B12: Assuntos sensíveis | C12: Encaminhar imediatamente usuário para atendimento humano em caso de assuntos sensíveis, como: Reclamação sobre entrega Solicitação de boleto Erros de informação Falar sobre um orçamento | D12: Todos os assuntos sensíveis devem ser encaminhados para o time de pós-vendas/atendimento ou Televendas. | E12: 1 - Importante

Sheet REQ Televendas
A1: Requisito | B1: Nome | C1: Descrição | D1: Critérios | E1: Prioridade | F1: Aderência
A2: #REQ04 | B2: Transbordo para atendimento humano | C2: Possibilitar handoff para o atendimento humano para contatos via Whatsapp em casos sem resolução ou com solicitação explícita de contato com humano. | D2: Time de Televendas e Pós-vendas/atendimento consegue entrar e responder as mensagens direcionadas para atendimento humano. O histórico da conversa entre o cliente e o agente permanece na conversa. Time de Televendas e Pós-vendas/atendimento consegue entrar e responder as mensagens direcionadas para atendimento humano. | E2: 0 - Obrigatória
A3: #REQ05 | B3: Redirecionamento de contato | C3: Permitir o encaminhamento de contato para outras filas ou contato. | D3: Deve haver um botão/função que permita o encaminhamento de um contato para outra fila ou contato. O histórico da conversa deve ser mantido. Após redirecionamento, o cliente não pode receber mensagem de saudação automática. | E3: 0 - Obrigatória
A4: #REQ06 | B4: Templates de mensagens | C4: Permitir a criação de frases prontas para agilizar o atendimento humano e que podem ser acessadas por atalhos, como o "/". Exemplo de frase: A Obramax agradece o seu contato. Até a próxima! | D4: O perfil Administrador deve ser capaz de criar mensagens padrão para que toda a sua equipe utilize. A equipe, por sua vez, pode utilizar esses templates por meio de um atalho para agilizar o atendimento. | E4: 1 - Importante
A5: #REQ07 | B5: Envio massivo de mensagens | C5: Permitir o envio de uma mensagem padrão ou customizada em massa para clientes, como boas vindas | D5: Deve haver a possibilidade de selecionar clientes. Deve ser permitido o envio de uma mensagem padrão do template ou personalizada. | E5: 1 - Importante
A6: #REQ08 | B6: Finalização de atendimento | C6: Permitir o vendedor colocar um motivo de encerramento caso tenha sido uma finalização por parte dele. Exemplos: Academia de Profissionais Achados e perdidos Alteração cadastral Cliente Ouvidoria Clube Obramax Consulta valor frete CredObra Desistiu Documento Recebido POV Dúvida sobre Produto Elogio/Reclamação Estorno Finalizou em outros canais Finalizou por ligação Fora do horário comercial Formas de pagamento Furo de estoque Dúvidas Loja Nota Fiscal Orçamento Parcelamento Problemas com pagamento Venda Faturada Venda Finalizada | D6: Finalizar atendimentos por inatividade caso o cliente não responda em X minutos. O vendedor deve ser capaz de finalizar um atendimento manualmente. O administrador tem a opção de incluir, editar e remover as opções de encerramento. O administrador pode configurar mensagem automática de encerramento para ser enviada ao cliente. | E6: 0 - Obrigatória
A7: #REQ11 | B7: Categorização de cliente | C7: Permitir a categorização com label, como "Cliente potencial". | D7: Criar o serviço de label para ser atrelada ao contato. Na tela de todas as conversas, deve ser possível filtrar os contatos com a label. | E7: 1 - Importante
A8: #REQ12 | B8: Confirmar itens em lista e quantidade caso o cliente mande mensagens listas. | C8: Enviar uma mensagem de confirmação em lista com todos os itens solicitados na conversa antes de montar um carrinho. | D8: Em caso de listas muito longas, seja em uma mídia, mensagem única ou diversas mensagens, o agente deve confirmar os itens e quantidade. Após a confirmação e antes de realizar a pesquisa, o agente deve informar que levará alguns minutos até terminar a pesquisa. Após retornar todos os itens, o agente deve questionar se o cliente deseja adicionar todos ao carrinho ou somente alguns (evitando a necessidade de remover posteriormente). | E8: 2 - Interessante
A9: #REQ22 | B9: Aprendizado contínuo | C9: Verificar o recurso atual e disponibilizar um espaço para atualização da base de conhecimento, permitindo aprendizado contínuo com base no dia-a-dia de usuários de pós-vendas e televendas. | D9: Interface simples para novas regras e políticas Obramax. Apenas perfis de usuários específicos poderiam adicionar instruções. Os usuários devem conseguir inserir e testar de forma autônoma as novas regras sem afetar o ambiente de produção. | E9: 2 - Interessante
A10: #REQ24 | B10: Assuntos sensíveis | C10: Encaminhar imediatamente usuário para atendimento humano em caso de assuntos sensíveis, como: Reclamação sobre entrega Solicitação de boleto Erros de informação Falar sobre um orçamento | D10: Todos os assuntos sensíveis devem ser encaminhados para o time de pós-vendas/atendimento ou Televendas. | E10: 1 - Importante

Sheet REQ CRM  Academia  Crédito
A1: Requisito | B1: Nome | C1: Descrição | D1: Critérios | E1: Prioridade | F1: Aderência
A2: #REQ17 | B2: Mensagens de marketing (CRM) | C2: Padronizar o fluxo de mensagens para que todas passem pelo mesmo cenário, facilitando análises e origens. Todas as campanhas do time de CRM devem ser centralizadas enviadas pela Weni. | D2: Deve haver uma opção de envio de ativações pelo time de CRM. | E2: 0 - Obrigatória
A3: #REQ19 | B3: Mensagens Academia de Profissionais | C3: Devemos implantar um fluxo AS IS com o mesmo tipo de opção que utilizam hoje. | D3: Deve haver uma opção de envio de ativações pelo time da Academia de Profissionais. | E3: 0 - Obrigatória

Sheet REQ Técnico
A1: Requisito | B1: Nome | C1: Descrição | D1: Critérios | E1: Prioridade | F1: Aderência
A2: #REQ01 | B2: Melhoria no tempo de resposta Weni | C2: Aplicar melhorias no atendimento, simplificando abordagens e processamento da IA | D2: O tempo de resposta médio para solicitações com 5 itens cai para 40s | E2: 1 - Importante
A3: #REQ02 | B3: Integração da Weni no Kafka | C3: Adicionar a Weni ao nosso ecossistema de integrações via Kafka para coletar mensagens, enviar dados e status entre a Weni e outros sistemas | D3: Solução Weni integrada ao nosso ambiente Captura de eventos Captura de logs para geração de relatórios e outros | E3: 1 - Importante
A4: #REQ03 | B4: Portabilidade telefones Obramax | C4: Solicitar portabilidade junto à Meta para que o número seja migrado para a nova solução. | D4: Número de telefone centralizados em uma só solução de broker e mensageria | E4: 0 - Obrigatória
A5: #REQ09 | B5: Melhoria em Agentes de IA | C5: Revisar a experiência dos agentes existentes para atender as necessidades de forma rápida e prática. | D5: A saudação deve ser mais enxuta e receptiva, como "Olá, sou o Especialista em construção da Obramax. Em que eu posso te ajudar hoje?" Com base na resposta, o agente deve direcionar para coletar a informação necessária. Ex: CEP para consultar produtos e informações de loja, número do pedido para consultar, etc. Se o cliente estiver irritado ou desejar falar com humano, transbordar para atendimento imediatamente. | E5: 2 - Interessante
A6: #REQ20 | B6: Monitoramento de disponibilidade | C6: Implantar um serviço de monitoramento (ex: Datadog) para acompanhamento de disponibilidade e fluxo de dados. | D6: Deve ser possível monitorar: Uptime Fluxo de requisições Desempenho de páginas Ameaças e padrões maliciosos Monitoramento de API | E6: 2 - Interessante
